Workbook

Sheet Notes
A1: Community United West Berkshire
A2: Ethnic group by age: West Berkshire, Reading and Wokingham
A3: Reference: CUDAT001 Version: v1.1.0
A4: Date: 30/09/2026
A5: Author: JMSH
A6: Status: Issued
A8: Item | B8: Detail
A9: Contents | B9: One tab per area gives counts (left) and each group's share of its age band (right). The Summary tab compares the three areas. The Jewish adjustment tab shows how the Jewish row was derived.
A10: Source | B10: Office for National Statistics (ONS), Census 2021, custom dataset: ethnic group (20 categories) by age (6 categories), usual residents, lower-tier local authority. Census Day was 21 March 2021.
A11: Jewish row | B11: "Jewish" was not a tick-box answer to the ethnic group question, but people could write it in. ONS counts those write-ins within Other White, Other Mixed and Any other ethnic group, depending on the heading they were written under. They have been moved out of those rows into a separate Jewish row, so the totals are unchanged.
A12: Jewish row – scope | B12: The row counts only people who wrote in Jewish as their ethnic group. Many more people gave Jewish as their religion, most of whom ticked White British as their ethnic group: 236 in West Berkshire, 329 in Reading and 435 in Wokingham (TS030, Religion). The Jewish row is therefore not a count of the Jewish population.
A13: Jewish row – ages | B13: ONS publishes the write-in counts (TS022, Ethnic group detailed) for all ages only. The age split is an estimate, made by applying the South East age profile of people who identified as Jewish through the ethnic group question (ONS, Jewish identity data: age and sex, table Jewish_5) and rounding to whole people. The all-ages Jewish figures are exact.
A14: Licence | B14: Source: Office for National Statistics, licensed under the Open Government Licence v3.0.
A15: Query | B15: https://api.beta.ons.gov.uk/v1/population-types/UR/census-observations?dimensions=ethnic_group_tb_20b,resident_age_6a&area-type=ltla,E06000037,E06000038,E06000041
A16: Accuracy | B16: ONS adds small random adjustments to cells to protect confidentiality. Group totals match the published TS021 (Ethnic group) table to within one to four people; White British matches exactly. Counts under 50 should be treated as approximate.
A17: Definitions | B17: "White British" is the Census category "White: English, Welsh, Scottish, Northern Irish or British". Percentages are shares of each age band, so each age column sums to 100%.
A18: Colour | B18: Figures in blue are keyed from the ONS sources, or, for the Jewish age split, calculated as described above. Everything else is a formula.

Sheet Summary
A1: Community United West Berkshire
A2: Ethnic group by age – comparison of the three areas
A3: Reference: CUDAT001 Version: v1.1.0
A4: All figures are formulas drawing on the area tabs.
A6: White British as a share of each age band
A7: Age band | B7: West Berkshire | C7: Reading | D7: Wokingham
A8: 0–15 | B8: ='West Berkshire'!J24 -> 0.82578965 | C8: =Reading!J24 -> 0.44487722 | D8: =Wokingham!J24 -> 0.63533261
A9: 16–24 | B9: ='West Berkshire'!K24 -> 0.86198061 | C9: =Reading!K24 -> 0.55882106 | D9: =Wokingham!K24 -> 0.72173052
A10: 25–34 | B10: ='West Berkshire'!L24 -> 0.80576482 | C10: =Reading!L24 -> 0.45180723 | D10: =Wokingham!L24 -> 0.71058777
A11: 35–49 | B11: ='West Berkshire'!M24 -> 0.78340383 | C11: =Reading!M24 -> 0.44110735 | D11: =Wokingham!M24 -> 0.61053136
A12: 50–64 | B12: ='West Berkshire'!N24 -> 0.89501748 | C12: =Reading!N24 -> 0.65279786 | D12: =Wokingham!N24 -> 0.81494973
A13: 65+ | B13: ='West Berkshire'!O24 -> 0.94518852 | C13: =Reading!O24 -> 0.78495495 | D13: =Wokingham!O24 -> 0.90457953
A14: All ages | B14: ='West Berkshire'!P24 -> 0.85633145 | C14: =Reading!P24 -> 0.53475718 | D14: =Wokingham!P24 -> 0.7272507
A17: Share of all usual residents, all ages
A18: Ethnic group | B18: West Berkshire | C18: Reading | D18: Wokingham
A19: Asian, Asian British or Asian Welsh | B19: ='West Berkshire'!P8 -> 0.037101729 | C19: =Reading!P8 -> 0.17702026 | D19: =Wokingham!P8 -> 0.12883944
A20: Bangladeshi | B20: ='West Berkshire'!P9 -> 0.002471384 | C20: =Reading!P9 -> 0.00649742 | D20: =Wokingham!P9 -> 0.0021859155
A21: Chinese | B21: ='West Berkshire'!P10 -> 0.0049613498 | C21: =Reading!P10 -> 0.015462941 | D21: =Wokingham!P10 -> 0.013476056
A22: Indian | B22: ='West Berkshire'!P11 -> 0.019095932 | C22: =Reading!P11 -> 0.061857504 | D22: =Wokingham!P11 -> 0.069926761
A23: Pakistani | B23: ='West Berkshire'!P12 -> 0.0040941975 | C23: =Reading!P12 -> 0.047519558 | D23: =Wokingham!P12 -> 0.029526761
A24: Other Asian | B24: ='West Berkshire'!P13 -> 0.0064788663 | C24: =Reading!P13 -> 0.045682832 | D24: =Wokingham!P13 -> 0.013723944
A25: Black, Black British, Black Welsh, Caribbean or African | B25: ='West Berkshire'!P14 -> 0.01259229 | C25: =Reading!P14 -> 0.071930801 | D25: =Wokingham!P14 -> 0.024253521
A26: African | B26: ='West Berkshire'!P15 -> 0.0067823696 | C26: =Reading!P15 -> 0.043995339 | D26: =Wokingham!P15 -> 0.016405634
A27: Caribbean | B27: ='West Berkshire'!P16 -> 0.0038836034 | C27: =Reading!P16 -> 0.018901064 | D27: =Wokingham!P16 -> 0.0048676056
A28: Other Black | B28: ='West Berkshire'!P17 -> 0.0019263168 | C28: =Reading!P17 -> 0.0090343984 | D28: =Wokingham!P17 -> 0.0029802817
A29: Mixed or Multiple ethnic groups | B29: ='West Berkshire'!P18 -> 0.023865269 | C29: =Reading!P18 -> 0.051393903 | D29: =Wokingham!P18 -> 0.031380282
A30: White and Asian | B30: ='West Berkshire'!P19 -> 0.0078910857 | C30: =Reading!P19 -> 0.012151094 | D30: =Wokingham!P19 -> 0.012461972
... A43: Jewish (written in as ethnic group) | B43: ='West Berkshire'!P32 -> 0.0003592488 | C43: =Reading!P32 -> 0.00059693611 | D43: =Wokingham!P32 -> 0.00054084507

Sheet West Berkshire
A1: Community United West Berkshire
A2: Ethnic group by age – West Berkshire
A3: Reference: CUDAT001 Version: v1.1.0
A4: Census 2021, usual residents. Source and notes on the Notes tab.
B6: Count of usual residents | J6: Share of age band
A7: Ethnic group | B7: 0–15 | C7: 16–24 | D7: 25–34 | E7: 35–49 | F7: 50–64 | G7: 65+ | H7: All ages | J7: 0–15 | K7: 16–24 | L7: 25–34 | M7: 35–49 | N7: 50–64 | O7: 65+ | P7: All ages
A8: Asian, Asian British or Asian Welsh | B8: =SUM(B9:B13) -> 1433 | C8: =SUM(C9:C13) -> 458 | D8: =SUM(D9:D13) -> 890 | E8: =SUM(E9:E13) -> 1990 | F8: =SUM(F9:F13) -> 851 | G8: =SUM(G9:G13) -> 368 | H8: =SUM(B8:G8) -> 5990 | J8: =IF(B$33=0,0,B8/B$33) -> 0.046662325 | K8: =IF(C$33=0,0,C8/C$33) -> 0.031717452 | L8: =IF(D$33=0,0,D8/D$33) -> 0.04858609 | M8: =IF(E$33=0,0,E8/E$33) -> 0.061893506 | N8: =IF(F$33=0,0,F8/F$33) -> 0.024796037 | O8: =IF(G$33=0,0,G8/G$33) -> 0.011679573 | P8: =IF(H$33=0,0,H8/H$33) -> 0.037101729
A9: Bangladeshi | B9: 124 | C9: 46 | D9: 69 | E9: 117 | F9: 28 | G9: 15 | H9: =SUM(B9:G9) -> 399 | J9: =IF(B$33=0,0,B9/B$33) -> 0.0040377727 | K9: =IF(C$33=0,0,C9/C$33) -> 0.0031855956 | L9: =IF(D$33=0,0,D9/D$33) -> 0.0037667868 | M9: =IF(E$33=0,0,E9/E$33) -> 0.0036389649 | N9: =IF(F$33=0,0,F9/F$33) -> 0.00081585082 | O9: =IF(G$33=0,0,G9/G$33) -> 0.00047606957 | P9: =IF(H$33=0,0,H9/H$33) -> 0.002471384
A10: Chinese | B10: 151 | C10: 90 | D10: 93 | E10: 224 | F10: 169 | G10: 74 | H10: =SUM(B10:G10) -> 801 | J10: =IF(B$33=0,0,B10/B$33) -> 0.0049169652 | K10: =IF(C$33=0,0,C10/C$33) -> 0.006232687 | L10: =IF(D$33=0,0,D10/D$33) -> 0.0050769735 | M10: =IF(E$33=0,0,E10/E$33) -> 0.0069669072 | N10: =IF(F$33=0,0,F10/F$33) -> 0.0049242424 | O10: =IF(G$33=0,0,G10/G$33) -> 0.0023486099 | P10: =IF(H$33=0,0,H10/H$33) -> 0.0049613498
A11: Indian | B11: 809 | C11: 153 | D11: 501 | E11: 1116 | F11: 338 | G11: 166 | H11: =SUM(B11:G11) -> 3083 | J11: =IF(B$33=0,0,B11/B$33) -> 0.026343211 | K11: =IF(C$33=0,0,C11/C$33) -> 0.010595568 | L11: =IF(D$33=0,0,D11/D$33) -> 0.027350147 | M11: =IF(E$33=0,0,E11/E$33) -> 0.034710127 | N11: =IF(F$33=0,0,F11/F$33) -> 0.0098484848 | O11: =IF(G$33=0,0,G11/G$33) -> 0.0052685032 | P11: =IF(H$33=0,0,H11/H$33) -> 0.019095932
A12: Pakistani | B12: 189 | C12: 68 | D12: 101 | E12: 181 | F12: 96 | G12: 26 | H12: =SUM(B12:G12) -> 661 | J12: =IF(B$33=0,0,B12/B$33) -> 0.0061543471 | K12: =IF(C$33=0,0,C12/C$33) -> 0.0047091413 | L12: =IF(D$33=0,0,D12/D$33) -> 0.0055137024 | M12: =IF(E$33=0,0,E12/E$33) -> 0.0056295098 | N12: =IF(F$33=0,0,F12/F$33) -> 0.0027972028 | O12: =IF(G$33=0,0,G12/G$33) -> 0.00082518725 | P12: =IF(H$33=0,0,H12/H$33) -> 0.0040941975
A13: Other Asian | B13: 160 | C13: 101 | D13: 126 | E13: 352 | F13: 220 | G13: 87 | H13: =SUM(B13:G13) -> 1046 | J13: =IF(B$33=0,0,B13/B$33) -> 0.0052100293 | K13: =IF(C$33=0,0,C13/C$33) -> 0.0069944598 | L13: =IF(D$33=0,0,D13/D$33) -> 0.0068784802 | M13: =IF(E$33=0,0,E13/E$33) -> 0.010947997 | N13: =IF(F$33=0,0,F13/F$33) -> 0.0064102564 | O13: =IF(G$33=0,0,G13/G$33) -> 0.0027612035 | P13: =IF(H$33=0,0,H13/H$33) -> 0.0064788663
A14: Black, Black British, Black Welsh, Caribbean or African | B14: =SUM(B15:B17) -> 433 | C14: =SUM(C15:C17) -> 196 | D14: =SUM(D15:D17) -> 236 | E14: =SUM(E15:E17) -> 537 | F14: =SUM(F15:F17) -> 484 | G14: =SUM(G15:G17) -> 147 | H14: =SUM(B14:G14) -> 2033 | J14: =IF(B$33=0,0,B14/B$33) -> 0.014099642 | K14: =IF(C$33=0,0,C14/C$33) -> 0.013573407 | L14: =IF(D$33=0,0,D14/D$33) -> 0.012883503 | M14: =IF(E$33=0,0,E14/E$33) -> 0.016701916 | N14: =IF(F$33=0,0,F14/F$33) -> 0.014102564 | O14: =IF(G$33=0,0,G14/G$33) -> 0.0046654818 | P14: =IF(H$33=0,0,H14/H$33) -> 0.01259229
A15: African | B15: 262 | C15: 122 | D15: 139 | E15: 356 | F15: 180 | G15: 36 | H15: =SUM(B15:G15) -> 1095 | J15: =IF(B$33=0,0,B15/B$33) -> 0.008531423 | K15: =IF(C$33=0,0,C15/C$33) -> 0.0084487535 | L15: =IF(D$33=0,0,D15/D$33) -> 0.0075881646 | M15: =IF(E$33=0,0,E15/E$33) -> 0.011072406 | N15: =IF(F$33=0,0,F15/F$33) -> 0.0052447552 | O15: =IF(G$33=0,0,G15/G$33) -> 0.001142567 | P15: =IF(H$33=0,0,H15/H$33) -> 0.0067823696
A16: Caribbean | B16: 57 | C16: 43 | D16: 71 | E16: 126 | F16: 241 | G16: 89 | H16: =SUM(B16:G16) -> 627 | J16: =IF(B$33=0,0,B16/B$33) -> 0.0018560729 | K16: =IF(C$33=0,0,C16/C$33) -> 0.0029778393 | L16: =IF(D$33=0,0,D16/D$33) -> 0.003875969 | M16: =IF(E$33=0,0,E16/E$33) -> 0.0039188853 | N16: =IF(F$33=0,0,F16/F$33) -> 0.0070221445 | O16: =IF(G$33=0,0,G16/G$33) -> 0.0028246794 | P16: =IF(H$33=0,0,H16/H$33) -> 0.0038836034
A17: Other Black | B17: 114 | C17: 31 | D17: 26 | E17: 55 | F17: 63 | G17: 22 | H17: =SUM(B17:G17) -> 311 | J17: =IF(B$33=0,0,B17/B$33) -> 0.0037121459 | K17: =IF(C$33=0,0,C17/C$33) -> 0.0021468144 | L17: =IF(D$33=0,0,D17/D$33) -> 0.0014193689 | M17: =IF(E$33=0,0,E17/E$33) -> 0.0017106245 | N17: =IF(F$33=0,0,F17/F$33) -> 0.0018356643 | O17: =IF(G$33=0,0,G17/G$33) -> 0.00069823537 | P17: =IF(H$33=0,0,H17/H$33) -> 0.0019263168
A18: Mixed or Multiple ethnic groups | B18: =SUM(B19:B22) -> 1798 | C18: =SUM(C19:C22) -> 593 | D18: =SUM(D19:D22) -> 470 | E18: =SUM(E19:E22) -> 578 | F18: =SUM(F19:F22) -> 313 | G18: =SUM(G19:G22) -> 101 | H18: =SUM(B18:G18) -> 3853 | J18: =IF(B$33=0,0,B18/B$33) -> 0.058547704 | K18: =IF(C$33=0,0,C18/C$33) -> 0.041066482 | L18: =IF(D$33=0,0,D18/D$33) -> 0.025657823 | M18: =IF(E$33=0,0,E18/E$33) -> 0.017977109 | N18: =IF(F$33=0,0,F18/F$33) -> 0.0091200466 | O18: =IF(G$33=0,0,G18/G$33) -> 0.0032055351 | P18: =IF(H$33=0,0,H18/H$33) -> 0.023865269
A19: White and Asian | B19: 683 | C19: 185 | D19: 129 | E19: 149 | F19: 96 | G19: 32 | H19: =SUM(B19:G19) -> 1274 | J19: =IF(B$33=0,0,B19/B$33) -> 0.022240313 | K19: =IF(C$33=0,0,C19/C$33) -> 0.012811634 | L19: =IF(D$33=0,0,D19/D$33) -> 0.0070422535 | M19: =IF(E$33=0,0,E19/E$33) -> 0.0046342374 | N19: =IF(F$33=0,0,F19/F$33) -> 0.0027972028 | O19: =IF(G$33=0,0,G19/G$33) -> 0.0010156151 | P19: =IF(H$33=0,0,H19/H$33) -> 0.0078910857
A20: White and Black African | B20: 248 | C20: 70 | D20: 52 | E20: 80 | F20: 39 | G20: 12 | H20: =SUM(B20:G20) -> 501 | J20: =IF(B$33=0,0,B20/B$33) -> 0.0080755454 | K20: =IF(C$33=0,0,C20/C$33) -> 0.0048476454 | L20: =IF(D$33=0,0,D20/D$33) -> 0.0028387379 | M20: =IF(E$33=0,0,E20/E$33) -> 0.0024881811 | N20: =IF(F$33=0,0,F20/F$33) -> 0.0011363636 | O20: =IF(G$33=0,0,G20/G$33) -> 0.00038085566 | P20: =IF(H$33=0,0,H20/H$33) -> 0.0031031663
A21: White and Black Caribbean | B21: 465 | C21: 202 | D21: 165 | E21: 136 | F21: 64 | G21: 23 | H21: =SUM(B21:G21) -> 1055 | J21: =IF(B$33=0,0,B21/B$33) -> 0.015141648 | K21: =IF(C$33=0,0,C21/C$33) -> 0.01398892 | L21: =IF(D$33=0,0,D21/D$33) -> 0.0090075336 | M21: =IF(E$33=0,0,E21/E$33) -> 0.0042299079 | N21: =IF(F$33=0,0,F21/F$33) -> 0.0018648019 | O21: =IF(G$33=0,0,G21/G$33) -> 0.00072997334 | P21: =IF(H$33=0,0,H21/H$33) -> 0.0065346118
A22: Other Mixed | B22: ='Jewish adjustment'!C22 -> 402 | C22: ='Jewish adjustment'!D22 -> 136 | D22: ='Jewish adjustment'!E22 -> 124 | E22: ='Jewish adjustment'!F22 -> 213 | F22: ='Jewish adjustment'!G22 -> 114 | G22: ='Jewish adjustment'!H22 -> 34 | H22: =SUM(B22:G22) -> 1023 | J22: =IF(B$33=0,0,B22/B$33) -> 0.013090199 | K22: =IF(C$33=0,0,C22/C$33) -> 0.0094182825 | L22: =IF(D$33=0,0,D22/D$33) -> 0.006769298 | M22: =IF(E$33=0,0,E22/E$33) -> 0.0066247823 | N22: =IF(F$33=0,0,F22/F$33) -> 0.0033216783 | O22: =IF(G$33=0,0,G22/G$33) -> 0.001079091 | P22: =IF(H$33=0,0,H22/H$33) -> 0.0063364055
A23: White | B23: =SUM(B24:B28) -> 26776 | C23: =SUM(C24:C28) -> 13093 | D23: =SUM(D24:D28) -> 16536 | E23: =SUM(E24:E28) -> 28671 | F23: =SUM(F24:F28) -> 32487 | G23: =SUM(G24:G28) -> 30783 | H23: =SUM(B23:G23) -> 148346 | J23: =IF(B$33=0,0,B23/B$33) -> 0.8718984 | K23: =IF(C$33=0,0,C23/C$33) -> 0.90671745 | L23: =IF(D$33=0,0,D23/D$33) -> 0.90271864 | M23: =IF(E$33=0,0,E23/E$33) -> 0.89173302 | N23: =IF(F$33=0,0,F23/F$33) -> 0.94659091 | O23: =IF(G$33=0,0,G23/G$33) -> 0.97698997 | P23: =IF(H$33=0,0,H23/H$33) -> 0.91884694
A24: White British | B24: 25360 | C24: 12447 | D24: 14760 | E24: 25188 | F24: 30717 | G24: 29781 | H24: =SUM(B24:G24) -> 138253 | J24: =IF(B$33=0,0,B24/B$33) -> 0.82578965 | K24: =IF(C$33=0,0,C24/C$33) -> 0.86198061 | L24: =IF(D$33=0,0,D24/D$33) -> 0.80576482 | M24: =IF(E$33=0,0,E24/E$33) -> 0.78340383 | N24: =IF(F$33=0,0,F24/F$33) -> 0.89501748 | O24: =IF(G$33=0,0,G24/G$33) -> 0.94518852 | P24: =IF(H$33=0,0,H24/H$33) -> 0.85633145
A25: Irish | B25: 79 | C25: 64 | D25: 136 | E25: 298 | F25: 420 | G25: 406 | H25: =SUM(B25:G25) -> 1403 | J25: =IF(B$33=0,0,B25/B$33) -> 0.002572452 | K25: =IF(C$33=0,0,C25/C$33) -> 0.004432133 | L25: =IF(D$33=0,0,D25/D$33) -> 0.0074243913 | M25: =IF(E$33=0,0,E25/E$33) -> 0.0092684747 | N25: =IF(F$33=0,0,F25/F$33) -> 0.012237762 | O25: =IF(G$33=0,0,G25/G$33) -> 0.012885616 | P25: =IF(H$33=0,0,H25/H$33) -> 0.0086901046
A26: Gypsy or Irish Traveller | B26: 71 | C26: 17 | D26: 34 | E26: 39 | F26: 20 | G26: 8 | H26: =SUM(B26:G26) -> 189 | J26: =IF(B$33=0,0,B26/B$33) -> 0.0023119505 | K26: =IF(C$33=0,0,C26/C$33) -> 0.0011772853 | L26: =IF(D$33=0,0,D26/D$33) -> 0.0018560978 | M26: =IF(E$33=0,0,E26/E$33) -> 0.0012129883 | N26: =IF(F$33=0,0,F26/F$33) -> 0.00058275058 | O26: =IF(G$33=0,0,G26/G$33) -> 0.00025390377 | P26: =IF(H$33=0,0,H26/H$33) -> 0.0011706556
A27: Roma | B27: 32 | C27: 15 | D27: 38 | E27: 52 | F27: 19 | G27: 3 | H27: =SUM(B27:G27) -> 159 | J27: =IF(B$33=0,0,B27/B$33) -> 0.0010420059 | K27: =IF(C$33=0,0,C27/C$33) -> 0.0010387812 | L27: =IF(D$33=0,0,D27/D$33) -> 0.0020744623 | M27: =IF(E$33=0,0,E27/E$33) -> 0.0016173177 | N27: =IF(F$33=0,0,F27/F$33) -> 0.00055361305 | O27: =IF(G$33=0,0,G27/G$33) -> 9.5213914e-05 | P27: =IF(H$33=0,0,H27/H$33) -> 0.00098483722
A28: Other White | B28: ='Jewish adjustment'!C16 -> 1234 | C28: ='Jewish adjustment'!D16 -> 550 | D28: ='Jewish adjustment'!E16 -> 1568 | E28: ='Jewish adjustment'!F16 -> 3094 | F28: ='Jewish adjustment'!G16 -> 1311 | G28: ='Jewish adjustment'!H16 -> 585 | H28: =SUM(B28:G28) -> 8342 | J28: =IF(B$33=0,0,B28/B$33) -> 0.040182351 | K28: =IF(C$33=0,0,C28/C$33) -> 0.038088643 | L28: =IF(D$33=0,0,D28/D$33) -> 0.085598865 | M28: =IF(E$33=0,0,E28/E$33) -> 0.096230406 | N28: =IF(F$33=0,0,F28/F$33) -> 0.038199301 | O28: =IF(G$33=0,0,G28/G$33) -> 0.018566713 | P28: =IF(H$33=0,0,H28/H$33) -> 0.051669888
A29: Other ethnic group | B29: =SUM(B30:B31) -> 264 | C29: =SUM(C30:C31) -> 94 | D29: =SUM(D30:D31) -> 180 | E29: =SUM(E30:E31) -> 363 | F29: =SUM(F30:F31) -> 171 | G29: =SUM(G30:G31) -> 96 | H29: =SUM(B29:G29) -> 1168 | J29: =IF(B$33=0,0,B29/B$33) -> 0.0085965484 | K29: =IF(C$33=0,0,C29/C$33) -> 0.0065096953 | L29: =IF(D$33=0,0,D29/D$33) -> 0.0098264003 | M29: =IF(E$33=0,0,E29/E$33) -> 0.011290122 | N29: =IF(F$33=0,0,F29/F$33) -> 0.0049825175 | O29: =IF(G$33=0,0,G29/G$33) -> 0.0030468452 | P29: =IF(H$33=0,0,H29/H$33) -> 0.0072345275
A30: Arab | B30: 88 | C30: 26 | D30: 32 | E30: 86 | F30: 34 | G30: 13 | H30: =SUM(B30:G30) -> 279 | J30: =IF(B$33=0,0,B30/B$33) -> 0.0028655161 | K30: =IF(C$33=0,0,C30/C$33) -> 0.001800554 | L30: =IF(D$33=0,0,D30/D$33) -> 0.0017469156 | M30: =IF(E$33=0,0,E30/E$33) -> 0.0026747947 | N30: =IF(F$33=0,0,F30/F$33) -> 0.00099067599 | O30: =IF(G$33=0,0,G30/G$33) -> 0.00041259363 | P30: =IF(H$33=0,0,H30/H$33) -> 0.0017281106
A31: Any other ethnic group | B31: ='Jewish adjustment'!C19 -> 176 | C31: ='Jewish adjustment'!D19 -> 68 | D31: ='Jewish adjustment'!E19 -> 148 | E31: ='Jewish adjustment'!F19 -> 277 | F31: ='Jewish adjustment'!G19 -> 137 | G31: ='Jewish adjustment'!H19 -> 83 | H31: =SUM(B31:G31) -> 889 | J31: =IF(B$33=0,0,B31/B$33) -> 0.0057310322 | K31: =IF(C$33=0,0,C31/C$33) -> 0.0047091413 | L31: =IF(D$33=0,0,D31/D$33) -> 0.0080794847 | M31: =IF(E$33=0,0,E31/E$33) -> 0.0086153272 | N31: =IF(F$33=0,0,F31/F$33) -> 0.0039918415 | O31: =IF(G$33=0,0,G31/G$33) -> 0.0026342516 | P31: =IF(H$33=0,0,H31/H$33) -> 0.0055064169
A32: Jewish (written in as ethnic group) – age split estimated | B32: ='Jewish adjustment'!C23 -> 6 | C32: ='Jewish adjustment'!D23 -> 6 | D32: ='Jewish adjustment'!E23 -> 6 | E32: ='Jewish adjustment'!F23 -> 13 | F32: ='Jewish adjustment'!G23 -> 14 | G32: ='Jewish adjustment'!H23 -> 13 | H32: =SUM(B32:G32) -> 58 | J32: =IF(B$33=0,0,B32/B$33) -> 0.0001953761 | K32: =IF(C$33=0,0,C32/C$33) -> 0.00041551247 | L32: =IF(D$33=0,0,D32/D$33) -> 0.00032754668 | M32: =IF(E$33=0,0,E32/E$33) -> 0.00040432944 | N32: =IF(F$33=0,0,F32/F$33) -> 0.00040792541 | O32: =IF(G$33=0,0,G32/G$33) -> 0.00041259363 | P32: =IF(H$33=0,0,H32/H$33) -> 0.0003592488
A33: All usual residents | B33: =B8+B14+B18+B23+B29+B32 -> 30710 | C33: =C8+C14+C18+C23+C29+C32 -> 14440 | D33: =D8+D14+D18+D23+D29+D32 -> 18318 | E33: =E8+E14+E18+E23+E29+E32 -> 32152 | F33: =F8+F14+F18+F23+F29+F32 -> 34320 | G33: =G8+G14+G18+G23+G29+G32 -> 31508 | H33: =SUM(B33:G33) -> 161448 | J33: =IF(B$33=0,0,B33/B$33) -> 1 | K33: =IF(C$33=0,0,C33/C$33) -> 1 | L33: =IF(D$33=0,0,D33/D$33) -> 1 | M33: =IF(E$33=0,0,E33/E$33) -> 1 | N33: =IF(F$33=0,0,F33/F$33) -> 1 | O33: =IF(G$33=0,0,G33/G$33) -> 1 | P33: =IF(H$33=0,0,H33/H$33) -> 1

Sheet Reading
A1: Community United West Berkshire
A2: Ethnic group by age – Reading
A3: Reference: CUDAT001 Version: v1.1.0
A4: Census 2021, usual residents. Source and notes on the Notes tab.
B6: Count of usual residents | J6: Share of age band
A7: Ethnic group | B7: 0–15 | C7: 16–24 | D7: 25–34 | E7: 35–49 | F7: 50–64 | G7: 65+ | H7: All ages | J7: 0–15 | K7: 16–24 | L7: 25–34 | M7: 35–49 | N7: 50–64 | O7: 65+ | P7: All ages
A8: Asian, Asian British or Asian Welsh | B8: =SUM(B9:B13) -> 7297 | C8: =SUM(C9:C13) -> 3710 | D8: =SUM(D9:D13) -> 6016 | E8: =SUM(E9:E13) -> 8685 | F8: =SUM(F9:F13) -> 3323 | G8: =SUM(G9:G13) -> 1810 | H8: =SUM(B8:G8) -> 30841 | J8: =IF(B$33=0,0,B8/B$33) -> 0.22204303 | K8: =IF(C$33=0,0,C8/C$33) -> 0.15598722 | L8: =IF(D$33=0,0,D8/D$33) -> 0.19912618 | M8: =IF(E$33=0,0,E8/E$33) -> 0.22428531 | N8: =IF(F$33=0,0,F8/F$33) -> 0.12012001 | O8: =IF(G$33=0,0,G8/G$33) -> 0.086284979 | P8: =IF(H$33=0,0,H8/H$33) -> 0.17702026
A9: Bangladeshi | B9: 315 | C9: 225 | D9: 170 | E9: 272 | F9: 125 | G9: 25 | H9: =SUM(B9:G9) -> 1132 | J9: =IF(B$33=0,0,B9/B$33) -> 0.0095852478 | K9: =IF(C$33=0,0,C9/C$33) -> 0.0094601413 | L9: =IF(D$33=0,0,D9/D$33) -> 0.0056269032 | M9: =IF(E$33=0,0,E9/E$33) -> 0.0070242492 | N9: =IF(F$33=0,0,F9/F$33) -> 0.0045185078 | O9: =IF(G$33=0,0,G9/G$33) -> 0.0011917815 | P9: =IF(H$33=0,0,H9/H$33) -> 0.00649742
A10: Chinese | B10: 416 | C10: 569 | D10: 587 | E10: 674 | F10: 322 | G10: 126 | H10: =SUM(B10:G10) -> 2694 | J10: =IF(B$33=0,0,B10/B$33) -> 0.012658613 | K10: =IF(C$33=0,0,C10/C$33) -> 0.023923646 | L10: =IF(D$33=0,0,D10/D$33) -> 0.019429366 | M10: =IF(E$33=0,0,E10/E$33) -> 0.017405676 | N10: =IF(F$33=0,0,F10/F$33) -> 0.011639676 | O10: =IF(G$33=0,0,G10/G$33) -> 0.0060065786 | P10: =IF(H$33=0,0,H10/H$33) -> 0.015462941
A11: Indian | B11: 2701 | C11: 957 | D11: 2152 | E11: 3678 | F11: 880 | G11: 409 | H11: =SUM(B11:G11) -> 10777 | J11: =IF(B$33=0,0,B11/B$33) -> 0.082189697 | K11: =IF(C$33=0,0,C11/C$33) -> 0.040237134 | L11: =IF(D$33=0,0,D11/D$33) -> 0.071229975 | M11: =IF(E$33=0,0,E11/E$33) -> 0.09498231 | N11: =IF(F$33=0,0,F11/F$33) -> 0.031810295 | O11: =IF(G$33=0,0,G11/G$33) -> 0.019497545 | P11: =IF(H$33=0,0,H11/H$33) -> 0.061857504
A12: Pakistani | B12: 2482 | C12: 1089 | D12: 1351 | E12: 2100 | F12: 817 | G12: 440 | H12: =SUM(B12:G12) -> 8279 | J12: =IF(B$33=0,0,B12/B$33) -> 0.075525667 | K12: =IF(C$33=0,0,C12/C$33) -> 0.045787084 | L12: =IF(D$33=0,0,D12/D$33) -> 0.044717331 | M12: =IF(E$33=0,0,E12/E$33) -> 0.054231335 | N12: =IF(F$33=0,0,F12/F$33) -> 0.029532967 | O12: =IF(G$33=0,0,G12/G$33) -> 0.020975354 | P12: =IF(H$33=0,0,H12/H$33) -> 0.047519558
A13: Other Asian | B13: 1383 | C13: 870 | D13: 1756 | E13: 1961 | F13: 1179 | G13: 810 | H13: =SUM(B13:G13) -> 7959 | J13: =IF(B$33=0,0,B13/B$33) -> 0.042083802 | K13: =IF(C$33=0,0,C13/C$33) -> 0.036579213 | L13: =IF(D$33=0,0,D13/D$33) -> 0.0581226 | M13: =IF(E$33=0,0,E13/E$33) -> 0.050641737 | N13: =IF(F$33=0,0,F13/F$33) -> 0.042618566 | O13: =IF(G$33=0,0,G13/G$33) -> 0.03861372 | P13: =IF(H$33=0,0,H13/H$33) -> 0.045682832
A14: Black, Black British, Black Welsh, Caribbean or African | B14: =SUM(B15:B17) -> 2741 | C14: =SUM(C15:C17) -> 1740 | D14: =SUM(D15:D17) -> 1793 | E14: =SUM(E15:E17) -> 2974 | F14: =SUM(F15:F17) -> 2450 | G14: =SUM(G15:G17) -> 834 | H14: =SUM(B14:G14) -> 12532 | J14: =IF(B$33=0,0,B14/B$33) -> 0.083406871 | K14: =IF(C$33=0,0,C14/C$33) -> 0.073158426 | L14: =IF(D$33=0,0,D14/D$33) -> 0.059347279 | M14: =IF(E$33=0,0,E14/E$33) -> 0.076801901 | N14: =IF(F$33=0,0,F14/F$33) -> 0.088562753 | O14: =IF(G$33=0,0,G14/G$33) -> 0.03975783 | P14: =IF(H$33=0,0,H14/H$33) -> 0.071930801
A15: African | B15: 1776 | C15: 1187 | D15: 1218 | E15: 2141 | F15: 1171 | G15: 172 | H15: =SUM(B15:G15) -> 7665 | J15: =IF(B$33=0,0,B15/B$33) -> 0.05404254 | K15: =IF(C$33=0,0,C15/C$33) -> 0.049907501 | L15: =IF(D$33=0,0,D15/D$33) -> 0.040315107 | M15: =IF(E$33=0,0,E15/E$33) -> 0.055290138 | N15: =IF(F$33=0,0,F15/F$33) -> 0.042329381 | O15: =IF(G$33=0,0,G15/G$33) -> 0.0081994565 | P15: =IF(H$33=0,0,H15/H$33) -> 0.043995339
A16: Caribbean | B16: 328 | C16: 329 | D16: 429 | E16: 635 | F16: 986 | G16: 586 | H16: =SUM(B16:G16) -> 3293 | J16: =IF(B$33=0,0,B16/B$33) -> 0.0099808295 | K16: =IF(C$33=0,0,C16/C$33) -> 0.013832829 | L16: =IF(D$33=0,0,D16/D$33) -> 0.014199656 | M16: =IF(E$33=0,0,E16/E$33) -> 0.016398523 | N16: =IF(F$33=0,0,F16/F$33) -> 0.03564199 | O16: =IF(G$33=0,0,G16/G$33) -> 0.027935358 | P16: =IF(H$33=0,0,H16/H$33) -> 0.018901064
A17: Other Black | B17: 637 | C17: 224 | D17: 146 | E17: 198 | F17: 293 | G17: 76 | H17: =SUM(B17:G17) -> 1574 | J17: =IF(B$33=0,0,B17/B$33) -> 0.019383501 | K17: =IF(C$33=0,0,C17/C$33) -> 0.0094180962 | L17: =IF(D$33=0,0,D17/D$33) -> 0.0048325169 | M17: =IF(E$33=0,0,E17/E$33) -> 0.0051132402 | N17: =IF(F$33=0,0,F17/F$33) -> 0.010591382 | O17: =IF(G$33=0,0,G17/G$33) -> 0.0036230157 | P17: =IF(H$33=0,0,H17/H$33) -> 0.0090343984
A18: Mixed or Multiple ethnic groups | B18: =SUM(B19:B22) -> 4119 | C18: =SUM(C19:C22) -> 1740 | D18: =SUM(D19:D22) -> 1309 | E18: =SUM(E19:E22) -> 1085 | F18: =SUM(F19:F22) -> 522 | G18: =SUM(G19:G22) -> 179 | H18: =SUM(B18:G18) -> 8954 | J18: =IF(B$33=0,0,B18/B$33) -> 0.12533853 | K18: =IF(C$33=0,0,C18/C$33) -> 0.073158426 | L18: =IF(D$33=0,0,D18/D$33) -> 0.043327155 | M18: =IF(E$33=0,0,E18/E$33) -> 0.028019523 | N18: =IF(F$33=0,0,F18/F$33) -> 0.018869289 | O18: =IF(G$33=0,0,G18/G$33) -> 0.0085331554 | P18: =IF(H$33=0,0,H18/H$33) -> 0.051393903
A19: White and Asian | B19: 1043 | C19: 420 | D19: 293 | E19: 214 | F19: 104 | G19: 43 | H19: =SUM(B19:G19) -> 2117 | J19: =IF(B$33=0,0,B19/B$33) -> 0.031737821 | K19: =IF(C$33=0,0,C19/C$33) -> 0.01765893 | L19: =IF(D$33=0,0,D19/D$33) -> 0.0096981332 | M19: =IF(E$33=0,0,E19/E$33) -> 0.0055264313 | N19: =IF(F$33=0,0,F19/F$33) -> 0.0037593985 | O19: =IF(G$33=0,0,G19/G$33) -> 0.0020498641 | P19: =IF(H$33=0,0,H19/H$33) -> 0.012151094
A20: White and Black African | B20: 612 | C20: 229 | D20: 137 | E20: 160 | F20: 84 | G20: 27 | H20: =SUM(B20:G20) -> 1249 | J20: =IF(B$33=0,0,B20/B$33) -> 0.018622767 | K20: =IF(C$33=0,0,C20/C$33) -> 0.0096283216 | L20: =IF(D$33=0,0,D20/D$33) -> 0.004534622 | M20: =IF(E$33=0,0,E20/E$33) -> 0.0041319113 | N20: =IF(F$33=0,0,F20/F$33) -> 0.0030364372 | O20: =IF(G$33=0,0,G20/G$33) -> 0.001287124 | P20: =IF(H$33=0,0,H20/H$33) -> 0.0071689731
A21: White and Black Caribbean | B21: 1676 | C21: 713 | D21: 565 | E21: 385 | F21: 173 | G21: 43 | H21: =SUM(B21:G21) -> 3555 | J21: =IF(B$33=0,0,B21/B$33) -> 0.050999604 | K21: =IF(C$33=0,0,C21/C$33) -> 0.029978137 | L21: =IF(D$33=0,0,D21/D$33) -> 0.018701178 | M21: =IF(E$33=0,0,E21/E$33) -> 0.0099424115 | N21: =IF(F$33=0,0,F21/F$33) -> 0.0062536148 | O21: =IF(G$33=0,0,G21/G$33) -> 0.0020498641 | P21: =IF(H$33=0,0,H21/H$33) -> 0.020404883
A22: Other Mixed | B22: ='Jewish adjustment'!C35 -> 788 | C22: ='Jewish adjustment'!D35 -> 378 | D22: ='Jewish adjustment'!E35 -> 314 | E22: ='Jewish adjustment'!F35 -> 326 | F22: ='Jewish adjustment'!G35 -> 161 | G22: ='Jewish adjustment'!H35 -> 66 | H22: =SUM(B22:G22) -> 2033 | J22: =IF(B$33=0,0,B22/B$33) -> 0.023978334 | K22: =IF(C$33=0,0,C22/C$33) -> 0.015893037 | L22: =IF(D$33=0,0,D22/D$33) -> 0.010393221 | M22: =IF(E$33=0,0,E22/E$33) -> 0.0084187692 | N22: =IF(F$33=0,0,F22/F$33) -> 0.0058198381 | O22: =IF(G$33=0,0,G22/G$33) -> 0.0031463031 | P22: =IF(H$33=0,0,H22/H$33) -> 0.011668953
A23: White | B23: =SUM(B24:B28) -> 17742 | C23: =SUM(C24:C28) -> 15897 | D23: =SUM(D24:D28) -> 20039 | E23: =SUM(E24:E28) -> 24640 | F23: =SUM(F24:F28) -> 20760 | G23: =SUM(G24:G28) -> 17765 | H23: =SUM(B23:G23) -> 116843 | J23: =IF(B$33=0,0,B23/B$33) -> 0.53987767 | K23: =IF(C$33=0,0,C23/C$33) -> 0.66839051 | L23: =IF(D$33=0,0,D23/D$33) -> 0.66327949 | M23: =IF(E$33=0,0,E23/E$33) -> 0.63631434 | N23: =IF(F$33=0,0,F23/F$33) -> 0.75043378 | O23: =IF(G$33=0,0,G23/G$33) -> 0.84687992 | P23: =IF(H$33=0,0,H23/H$33) -> 0.67065198
A24: White British | B24: 14620 | C24: 13291 | D24: 13650 | E24: 17081 | F24: 18059 | G24: 16466 | H24: =SUM(B24:G24) -> 93167 | J24: =IF(B$33=0,0,B24/B$33) -> 0.44487722 | K24: =IF(C$33=0,0,C24/C$33) -> 0.55882106 | L24: =IF(D$33=0,0,D24/D$33) -> 0.45180723 | M24: =IF(E$33=0,0,E24/E$33) -> 0.44110735 | N24: =IF(F$33=0,0,F24/F$33) -> 0.65279786 | O24: =IF(G$33=0,0,G24/G$33) -> 0.78495495 | P24: =IF(H$33=0,0,H24/H$33) -> 0.53475718
A25: Irish | B25: 95 | C25: 160 | D25: 333 | E25: 426 | F25: 496 | G25: 529 | H25: =SUM(B25:G25) -> 2039 | J25: =IF(B$33=0,0,B25/B$33) -> 0.002890789 | K25: =IF(C$33=0,0,C25/C$33) -> 0.0067272116 | L25: =IF(D$33=0,0,D25/D$33) -> 0.01102211 | M25: =IF(E$33=0,0,E25/E$33) -> 0.011001214 | N25: =IF(F$33=0,0,F25/F$33) -> 0.017929439 | O25: =IF(G$33=0,0,G25/G$33) -> 0.025218096 | P25: =IF(H$33=0,0,H25/H$33) -> 0.011703392
A26: Gypsy or Irish Traveller | B26: 24 | C26: 24 | D26: 27 | E26: 10 | F26: 16 | G26: 7 | H26: =SUM(B26:G26) -> 108 | J26: =IF(B$33=0,0,B26/B$33) -> 0.0007303046 | K26: =IF(C$33=0,0,C26/C$33) -> 0.0010090817 | L26: =IF(D$33=0,0,D26/D$33) -> 0.00089368463 | M26: =IF(E$33=0,0,E26/E$33) -> 0.00025824445 | N26: =IF(F$33=0,0,F26/F$33) -> 0.000578369 | O26: =IF(G$33=0,0,G26/G$33) -> 0.00033369881 | P26: =IF(H$33=0,0,H26/H$33) -> 0.00061989519
A27: Roma | B27: 78 | C27: 83 | D27: 206 | E27: 155 | F27: 43 | G27: 8 | H27: =SUM(B27:G27) -> 573 | J27: =IF(B$33=0,0,B27/B$33) -> 0.0023734899 | K27: =IF(C$33=0,0,C27/C$33) -> 0.003489741 | L27: =IF(D$33=0,0,D27/D$33) -> 0.0068184827 | M27: =IF(E$33=0,0,E27/E$33) -> 0.004002789 | N27: =IF(F$33=0,0,F27/F$33) -> 0.0015543667 | O27: =IF(G$33=0,0,G27/G$33) -> 0.00038137007 | P27: =IF(H$33=0,0,H27/H$33) -> 0.0032888884
A28: Other White | B28: ='Jewish adjustment'!C29 -> 2925 | C28: ='Jewish adjustment'!D29 -> 2339 | D28: ='Jewish adjustment'!E29 -> 5823 | E28: ='Jewish adjustment'!F29 -> 6968 | F28: ='Jewish adjustment'!G29 -> 2146 | G28: ='Jewish adjustment'!H29 -> 755 | H28: =SUM(B28:G28) -> 20956 | J28: =IF(B$33=0,0,B28/B$33) -> 0.089005873 | K28: =IF(C$33=0,0,C28/C$33) -> 0.098343424 | L28: =IF(D$33=0,0,D28/D$33) -> 0.19273798 | M28: =IF(E$33=0,0,E28/E$33) -> 0.17994474 | N28: =IF(F$33=0,0,F28/F$33) -> 0.077573742 | O28: =IF(G$33=0,0,G28/G$33) -> 0.035991801 | P28: =IF(H$33=0,0,H28/H$33) -> 0.12028263
A29: Other ethnic group | B29: =SUM(B30:B31) -> 952 | C29: =SUM(C30:C31) -> 684 | D29: =SUM(D30:D31) -> 1045 | E29: =SUM(E30:E31) -> 1317 | F29: =SUM(F30:F31) -> 583 | G29: =SUM(G30:G31) -> 368 | H29: =SUM(B29:G29) -> 4949 | J29: =IF(B$33=0,0,B29/B$33) -> 0.028968749 | K29: =IF(C$33=0,0,C29/C$33) -> 0.028758829 | L29: =IF(D$33=0,0,D29/D$33) -> 0.034588905 | M29: =IF(E$33=0,0,E29/E$33) -> 0.034010795 | N29: =IF(F$33=0,0,F29/F$33) -> 0.02107432 | O29: =IF(G$33=0,0,G29/G$33) -> 0.017543023 | P29: =IF(H$33=0,0,H29/H$33) -> 0.028406123
A30: Arab | B30: 352 | C30: 214 | D30: 273 | E30: 321 | F30: 90 | G30: 32 | H30: =SUM(B30:G30) -> 1282 | J30: =IF(B$33=0,0,B30/B$33) -> 0.010711134 | K30: =IF(C$33=0,0,C30/C$33) -> 0.0089976455 | L30: =IF(D$33=0,0,D30/D$33) -> 0.0090361446 | M30: =IF(E$33=0,0,E30/E$33) -> 0.008289647 | N30: =IF(F$33=0,0,F30/F$33) -> 0.0032533256 | O30: =IF(G$33=0,0,G30/G$33) -> 0.0015254803 | P30: =IF(H$33=0,0,H30/H$33) -> 0.0073583855
A31: Any other ethnic group | B31: ='Jewish adjustment'!C32 -> 600 | C31: ='Jewish adjustment'!D32 -> 470 | D31: ='Jewish adjustment'!E32 -> 772 | E31: ='Jewish adjustment'!F32 -> 996 | F31: ='Jewish adjustment'!G32 -> 493 | G31: ='Jewish adjustment'!H32 -> 336 | H31: =SUM(B31:G31) -> 3667 | J31: =IF(B$33=0,0,B31/B$33) -> 0.018257615 | K31: =IF(C$33=0,0,C31/C$33) -> 0.019761184 | L31: =IF(D$33=0,0,D31/D$33) -> 0.02555276 | M31: =IF(E$33=0,0,E31/E$33) -> 0.025721148 | N31: =IF(F$33=0,0,F31/F$33) -> 0.017820995 | O31: =IF(G$33=0,0,G31/G$33) -> 0.016017543 | P31: =IF(H$33=0,0,H31/H$33) -> 0.021047738
A32: Jewish (written in as ethnic group) – age split estimated | B32: ='Jewish adjustment'!C36 -> 12 | C32: ='Jewish adjustment'!D36 -> 13 | D32: ='Jewish adjustment'!E36 -> 10 | E32: ='Jewish adjustment'!F36 -> 22 | F32: ='Jewish adjustment'!G36 -> 26 | G32: ='Jewish adjustment'!H36 -> 21 | H32: =SUM(B32:G32) -> 104 | J32: =IF(B$33=0,0,B32/B$33) -> 0.0003651523 | K32: =IF(C$33=0,0,C32/C$33) -> 0.00054658594 | L32: =IF(D$33=0,0,D32/D$33) -> 0.00033099431 | M32: =IF(E$33=0,0,E32/E$33) -> 0.0005681378 | N32: =IF(F$33=0,0,F32/F$33) -> 0.00093984962 | O32: =IF(G$33=0,0,G32/G$33) -> 0.0010010964 | P32: =IF(H$33=0,0,H32/H$33) -> 0.00059693611
A33: All usual residents | B33: =B8+B14+B18+B23+B29+B32 -> 32863 | C33: =C8+C14+C18+C23+C29+C32 -> 23784 | D33: =D8+D14+D18+D23+D29+D32 -> 30212 | E33: =E8+E14+E18+E23+E29+E32 -> 38723 | F33: =F8+F14+F18+F23+F29+F32 -> 27664 | G33: =G8+G14+G18+G23+G29+G32 -> 20977 | H33: =SUM(B33:G33) -> 174223 | J33: =IF(B$33=0,0,B33/B$33) -> 1 | K33: =IF(C$33=0,0,C33/C$33) -> 1 | L33: =IF(D$33=0,0,D33/D$33) -> 1 | M33: =IF(E$33=0,0,E33/E$33) -> 1 | N33: =IF(F$33=0,0,F33/F$33) -> 1 | O33: =IF(G$33=0,0,G33/G$33) -> 1 | P33: =IF(H$33=0,0,H33/H$33) -> 1

Sheet Wokingham
A1: Community United West Berkshire
A2: Ethnic group by age – Wokingham
A3: Reference: CUDAT001 Version: v1.1.0
A4: Census 2021, usual residents. Source and notes on the Notes tab.
B6: Count of usual residents | J6: Share of age band
A7: Ethnic group | B7: 0–15 | C7: 16–24 | D7: 25–34 | E7: 35–49 | F7: 50–64 | G7: 65+ | H7: All ages | J7: 0–15 | K7: 16–24 | L7: 25–34 | M7: 35–49 | N7: 50–64 | O7: 65+ | P7: All ages
A8: Asian, Asian British or Asian Welsh | B8: =SUM(B9:B13) -> 6472 | C8: =SUM(C9:C13) -> 1981 | D8: =SUM(D9:D13) -> 2422 | E8: =SUM(E9:E13) -> 8053 | F8: =SUM(F9:F13) -> 2710 | G8: =SUM(G9:G13) -> 1231 | H8: =SUM(B8:G8) -> 22869 | J8: =IF(B$33=0,0,B8/B$33) -> 0.17644493 | K8: =IF(C$33=0,0,C8/C$33) -> 0.1226094 | L8: =IF(D$33=0,0,D8/D$33) -> 0.12033587 | M8: =IF(E$33=0,0,E8/E$33) -> 0.20298951 | N8: =IF(F$33=0,0,F8/F$33) -> 0.07897421 | O8: =IF(G$33=0,0,G8/G$33) -> 0.040295918 | P8: =IF(H$33=0,0,H8/H$33) -> 0.12883944
A9: Bangladeshi | B9: 111 | C9: 58 | D9: 50 | E9: 109 | F9: 46 | G9: 14 | H9: =SUM(B9:G9) -> 388 | J9: =IF(B$33=0,0,B9/B$33) -> 0.0030261723 | K9: =IF(C$33=0,0,C9/C$33) -> 0.0035897753 | L9: =IF(D$33=0,0,D9/D$33) -> 0.0024842252 | M9: =IF(E$33=0,0,E9/E$33) -> 0.0027475297 | N9: =IF(F$33=0,0,F9/F$33) -> 0.0013405216 | O9: =IF(G$33=0,0,G9/G$33) -> 0.00045828014 | P9: =IF(H$33=0,0,H9/H$33) -> 0.0021859155
A10: Chinese | B10: 595 | C10: 220 | D10: 237 | E10: 819 | F10: 380 | G10: 141 | H10: =SUM(B10:G10) -> 2392 | J10: =IF(B$33=0,0,B10/B$33) -> 0.016221374 | K10: =IF(C$33=0,0,C10/C$33) -> 0.013616389 | L10: =IF(D$33=0,0,D10/D$33) -> 0.011775227 | M10: =IF(E$33=0,0,E10/E$33) -> 0.020644283 | N10: =IF(F$33=0,0,F10/F$33) -> 0.011073874 | O10: =IF(G$33=0,0,G10/G$33) -> 0.0046155357 | P10: =IF(H$33=0,0,H10/H$33) -> 0.013476056
A11: Indian | B11: 3541 | C11: 867 | D11: 1132 | E11: 4863 | F11: 1370 | G11: 639 | H11: =SUM(B11:G11) -> 12412 | J11: =IF(B$33=0,0,B11/B$33) -> 0.096537623 | K11: =IF(C$33=0,0,C11/C$33) -> 0.053660952 | L11: =IF(D$33=0,0,D11/D$33) -> 0.056242858 | M11: =IF(E$33=0,0,E11/E$33) -> 0.12258016 | N11: =IF(F$33=0,0,F11/F$33) -> 0.039924231 | O11: =IF(G$33=0,0,G11/G$33) -> 0.020917215 | P11: =IF(H$33=0,0,H11/H$33) -> 0.069926761
A12: Pakistani | B12: 1717 | C12: 613 | D12: 702 | E12: 1428 | F12: 522 | G12: 259 | H12: =SUM(B12:G12) -> 5241 | J12: =IF(B$33=0,0,B12/B$33) -> 0.046810251 | K12: =IF(C$33=0,0,C12/C$33) -> 0.037940212 | L12: =IF(D$33=0,0,D12/D$33) -> 0.034878521 | M12: =IF(E$33=0,0,E12/E$33) -> 0.03599516 | N12: =IF(F$33=0,0,F12/F$33) -> 0.015212006 | O12: =IF(G$33=0,0,G12/G$33) -> 0.0084781826 | P12: =IF(H$33=0,0,H12/H$33) -> 0.029526761
A13: Other Asian | B13: 508 | C13: 223 | D13: 301 | E13: 834 | F13: 392 | G13: 178 | H13: =SUM(B13:G13) -> 2436 | J13: =IF(B$33=0,0,B13/B$33) -> 0.013849509 | K13: =IF(C$33=0,0,C13/C$33) -> 0.013802067 | L13: =IF(D$33=0,0,D13/D$33) -> 0.014955036 | M13: =IF(E$33=0,0,E13/E$33) -> 0.021022384 | N13: =IF(F$33=0,0,F13/F$33) -> 0.011423576 | O13: =IF(G$33=0,0,G13/G$33) -> 0.0058267046 | P13: =IF(H$33=0,0,H13/H$33) -> 0.013723944
A14: Black, Black British, Black Welsh, Caribbean or African | B14: =SUM(B15:B17) -> 1165 | C14: =SUM(C15:C17) -> 466 | D14: =SUM(D15:D17) -> 494 | E14: =SUM(E15:E17) -> 1232 | F14: =SUM(F15:F17) -> 736 | G14: =SUM(G15:G17) -> 212 | H14: =SUM(B14:G14) -> 4305 | J14: =IF(B$33=0,0,B14/B$33) -> 0.031761178 | K14: =IF(C$33=0,0,C14/C$33) -> 0.028841988 | L14: =IF(D$33=0,0,D14/D$33) -> 0.024544145 | M14: =IF(E$33=0,0,E14/E$33) -> 0.031054648 | N14: =IF(F$33=0,0,F14/F$33) -> 0.021448346 | O14: =IF(G$33=0,0,G14/G$33) -> 0.0069396707 | P14: =IF(H$33=0,0,H14/H$33) -> 0.024253521
A15: African | B15: 839 | C15: 335 | D15: 348 | E15: 947 | F15: 388 | G15: 55 | H15: =SUM(B15:G15) -> 2912 | J15: =IF(B$33=0,0,B15/B$33) -> 0.022873501 | K15: =IF(C$33=0,0,C15/C$33) -> 0.020734047 | L15: =IF(D$33=0,0,D15/D$33) -> 0.017290207 | M15: =IF(E$33=0,0,E15/E$33) -> 0.02387074 | N15: =IF(F$33=0,0,F15/F$33) -> 0.011307009 | O15: =IF(G$33=0,0,G15/G$33) -> 0.0018003863 | P15: =IF(H$33=0,0,H15/H$33) -> 0.016405634
A16: Caribbean | B16: 74 | C16: 64 | D16: 102 | E16: 205 | F16: 272 | G16: 147 | H16: =SUM(B16:G16) -> 864 | J16: =IF(B$33=0,0,B16/B$33) -> 0.0020174482 | K16: =IF(C$33=0,0,C16/C$33) -> 0.0039611314 | L16: =IF(D$33=0,0,D16/D$33) -> 0.0050678193 | M16: =IF(E$33=0,0,E16/E$33) -> 0.0051673725 | N16: =IF(F$33=0,0,F16/F$33) -> 0.0079265627 | O16: =IF(G$33=0,0,G16/G$33) -> 0.0048119415 | P16: =IF(H$33=0,0,H16/H$33) -> 0.0048676056
A17: Other Black | B17: 252 | C17: 67 | D17: 44 | E17: 80 | F17: 76 | G17: 10 | H17: =SUM(B17:G17) -> 529 | J17: =IF(B$33=0,0,B17/B$33) -> 0.006870229 | K17: =IF(C$33=0,0,C17/C$33) -> 0.0041468094 | L17: =IF(D$33=0,0,D17/D$33) -> 0.0021861181 | M17: =IF(E$33=0,0,E17/E$33) -> 0.0020165356 | N17: =IF(F$33=0,0,F17/F$33) -> 0.0022147749 | O17: =IF(G$33=0,0,G17/G$33) -> 0.00032734296 | P17: =IF(H$33=0,0,H17/H$33) -> 0.0029802817
A18: Mixed or Multiple ethnic groups | B18: =SUM(B19:B22) -> 2854 | C18: =SUM(C19:C22) -> 831 | D18: =SUM(D19:D22) -> 665 | E18: =SUM(E19:E22) -> 695 | F18: =SUM(F19:F22) -> 416 | G18: =SUM(G19:G22) -> 109 | H18: =SUM(B18:G18) -> 5570 | J18: =IF(B$33=0,0,B18/B$33) -> 0.07780807 | K18: =IF(C$33=0,0,C18/C$33) -> 0.051432815 | L18: =IF(D$33=0,0,D18/D$33) -> 0.033040195 | M18: =IF(E$33=0,0,E18/E$33) -> 0.017518653 | N18: =IF(F$33=0,0,F18/F$33) -> 0.012122978 | O18: =IF(G$33=0,0,G18/G$33) -> 0.0035680382 | P18: =IF(H$33=0,0,H18/H$33) -> 0.031380282
A19: White and Asian | B19: 1248 | C19: 308 | D19: 224 | E19: 233 | F19: 155 | G19: 44 | H19: =SUM(B19:G19) -> 2212 | J19: =IF(B$33=0,0,B19/B$33) -> 0.034023991 | K19: =IF(C$33=0,0,C19/C$33) -> 0.019062945 | L19: =IF(D$33=0,0,D19/D$33) -> 0.011129329 | M19: =IF(E$33=0,0,E19/E$33) -> 0.0058731599 | N19: =IF(F$33=0,0,F19/F$33) -> 0.0045169751 | O19: =IF(G$33=0,0,G19/G$33) -> 0.001440309 | P19: =IF(H$33=0,0,H19/H$33) -> 0.012461972
A20: White and Black African | B20: 398 | C20: 93 | D20: 55 | E20: 68 | F20: 48 | G20: 4 | H20: =SUM(B20:G20) -> 666 | J20: =IF(B$33=0,0,B20/B$33) -> 0.0108506 | K20: =IF(C$33=0,0,C20/C$33) -> 0.0057560191 | L20: =IF(D$33=0,0,D20/D$33) -> 0.0027326477 | M20: =IF(E$33=0,0,E20/E$33) -> 0.0017140553 | N20: =IF(F$33=0,0,F20/F$33) -> 0.0013988052 | O20: =IF(G$33=0,0,G20/G$33) -> 0.00013093718 | P20: =IF(H$33=0,0,H20/H$33) -> 0.0037521127
A21: White and Black Caribbean | B21: 574 | C21: 241 | D21: 230 | E21: 144 | F21: 86 | G21: 29 | H21: =SUM(B21:G21) -> 1304 | J21: =IF(B$33=0,0,B21/B$33) -> 0.015648855 | K21: =IF(C$33=0,0,C21/C$33) -> 0.014916135 | L21: =IF(D$33=0,0,D21/D$33) -> 0.011427436 | M21: =IF(E$33=0,0,E21/E$33) -> 0.0036297641 | N21: =IF(F$33=0,0,F21/F$33) -> 0.0025061926 | O21: =IF(G$33=0,0,G21/G$33) -> 0.00094929458 | P21: =IF(H$33=0,0,H21/H$33) -> 0.0073464789
A22: Other Mixed | B22: ='Jewish adjustment'!C48 -> 634 | C22: ='Jewish adjustment'!D48 -> 189 | D22: ='Jewish adjustment'!E48 -> 156 | E22: ='Jewish adjustment'!F48 -> 250 | F22: ='Jewish adjustment'!G48 -> 127 | G22: ='Jewish adjustment'!H48 -> 32 | H22: =SUM(B22:G22) -> 1388 | J22: =IF(B$33=0,0,B22/B$33) -> 0.017284624 | K22: =IF(C$33=0,0,C22/C$33) -> 0.011697716 | L22: =IF(D$33=0,0,D22/D$33) -> 0.0077507825 | M22: =IF(E$33=0,0,E22/E$33) -> 0.0063016737 | N22: =IF(F$33=0,0,F22/F$33) -> 0.0037010054 | O22: =IF(G$33=0,0,G22/G$33) -> 0.0010474975 | P22: =IF(H$33=0,0,H22/H$33) -> 0.0078197183
A23: White | B23: =SUM(B24:B28) -> 25422 | C23: =SUM(C24:C28) -> 12599 | D23: =SUM(D24:D28) -> 16188 | E23: =SUM(E24:E28) -> 28823 | F23: =SUM(F24:F28) -> 30013 | G23: =SUM(G24:G28) -> 28761 | H23: =SUM(B23:G23) -> 141806 | J23: =IF(B$33=0,0,B23/B$33) -> 0.69307525 | K23: =IF(C$33=0,0,C23/C$33) -> 0.77978585 | L23: =IF(D$33=0,0,D23/D$33) -> 0.80429274 | M23: =IF(E$33=0,0,E23/E$33) -> 0.72653257 | N23: =IF(F$33=0,0,F23/F$33) -> 0.87463209 | O23: =IF(G$33=0,0,G23/G$33) -> 0.94147108 | P23: =IF(H$33=0,0,H23/H$33) -> 0.79890704
A24: White British | B24: 23304 | C24: 11661 | D24: 14302 | E24: 24221 | F24: 27965 | G24: 27634 | H24: =SUM(B24:G24) -> 129087 | J24: =IF(B$33=0,0,B24/B$33) -> 0.63533261 | K24: =IF(C$33=0,0,C24/C$33) -> 0.72173052 | L24: =IF(D$33=0,0,D24/D$33) -> 0.71058777 | M24: =IF(E$33=0,0,E24/E$33) -> 0.61053136 | N24: =IF(F$33=0,0,F24/F$33) -> 0.81494973 | O24: =IF(G$33=0,0,G24/G$33) -> 0.90457953 | P24: =IF(H$33=0,0,H24/H$33) -> 0.7272507
A25: Irish | B25: 105 | C25: 80 | D25: 122 | E25: 347 | F25: 432 | G25: 418 | H25: =SUM(B25:G25) -> 1504 | J25: =IF(B$33=0,0,B25/B$33) -> 0.0028625954 | K25: =IF(C$33=0,0,C25/C$33) -> 0.0049514142 | L25: =IF(D$33=0,0,D25/D$33) -> 0.0060615094 | M25: =IF(E$33=0,0,E25/E$33) -> 0.0087467231 | N25: =IF(F$33=0,0,F25/F$33) -> 0.012589247 | O25: =IF(G$33=0,0,G25/G$33) -> 0.013682936 | P25: =IF(H$33=0,0,H25/H$33) -> 0.0084732394
A26: Gypsy or Irish Traveller | B26: 115 | C26: 47 | D26: 40 | E26: 54 | F26: 45 | G26: 28 | H26: =SUM(B26:G26) -> 329 | J26: =IF(B$33=0,0,B26/B$33) -> 0.0031352236 | K26: =IF(C$33=0,0,C26/C$33) -> 0.0029089559 | L26: =IF(D$33=0,0,D26/D$33) -> 0.0019873801 | M26: =IF(E$33=0,0,E26/E$33) -> 0.0013611615 | N26: =IF(F$33=0,0,F26/F$33) -> 0.0013113799 | O26: =IF(G$33=0,0,G26/G$33) -> 0.00091656028 | P26: =IF(H$33=0,0,H26/H$33) -> 0.0018535211
A27: Roma | B27: 23 | C27: 17 | D27: 46 | E27: 67 | F27: 22 | G27: 7 | H27: =SUM(B27:G27) -> 182 | J27: =IF(B$33=0,0,B27/B$33) -> 0.00062704471 | K27: =IF(C$33=0,0,C27/C$33) -> 0.0010521755 | L27: =IF(D$33=0,0,D27/D$33) -> 0.0022854872 | M27: =IF(E$33=0,0,E27/E$33) -> 0.0016888486 | N27: =IF(F$33=0,0,F27/F$33) -> 0.00064111904 | O27: =IF(G$33=0,0,G27/G$33) -> 0.00022914007 | P27: =IF(H$33=0,0,H27/H$33) -> 0.0010253521
A28: Other White | B28: ='Jewish adjustment'!C42 -> 1875 | C28: ='Jewish adjustment'!D42 -> 794 | D28: ='Jewish adjustment'!E42 -> 1678 | E28: ='Jewish adjustment'!F42 -> 4134 | F28: ='Jewish adjustment'!G42 -> 1549 | G28: ='Jewish adjustment'!H42 -> 674 | H28: =SUM(B28:G28) -> 10704 | J28: =IF(B$33=0,0,B28/B$33) -> 0.051117775 | K28: =IF(C$33=0,0,C28/C$33) -> 0.049142786 | L28: =IF(D$33=0,0,D28/D$33) -> 0.083370597 | M28: =IF(E$33=0,0,E28/E$33) -> 0.10420448 | N28: =IF(F$33=0,0,F28/F$33) -> 0.045140609 | O28: =IF(G$33=0,0,G28/G$33) -> 0.022062915 | P28: =IF(H$33=0,0,H28/H$33) -> 0.060304225
A29: Other ethnic group | B29: =SUM(B30:B31) -> 756 | C29: =SUM(C30:C31) -> 268 | D29: =SUM(D30:D31) -> 349 | E29: =SUM(E30:E31) -> 849 | F29: =SUM(F30:F31) -> 416 | G29: =SUM(G30:G31) -> 216 | H29: =SUM(B29:G29) -> 2854 | J29: =IF(B$33=0,0,B29/B$33) -> 0.020610687 | K29: =IF(C$33=0,0,C29/C$33) -> 0.016587238 | L29: =IF(D$33=0,0,D29/D$33) -> 0.017339892 | M29: =IF(E$33=0,0,E29/E$33) -> 0.021400484 | N29: =IF(F$33=0,0,F29/F$33) -> 0.012122978 | O29: =IF(G$33=0,0,G29/G$33) -> 0.0070706079 | P29: =IF(H$33=0,0,H29/H$33) -> 0.016078873
A30: Arab | B30: 318 | C30: 119 | D30: 123 | E30: 252 | F30: 103 | G30: 33 | H30: =SUM(B30:G30) -> 948 | J30: =IF(B$33=0,0,B30/B$33) -> 0.0086695747 | K30: =IF(C$33=0,0,C30/C$33) -> 0.0073652287 | L30: =IF(D$33=0,0,D30/D$33) -> 0.0061111939 | M30: =IF(E$33=0,0,E30/E$33) -> 0.0063520871 | N30: =IF(F$33=0,0,F30/F$33) -> 0.0030016028 | O30: =IF(G$33=0,0,G30/G$33) -> 0.0010802318 | P30: =IF(H$33=0,0,H30/H$33) -> 0.0053408451
A31: Any other ethnic group | B31: ='Jewish adjustment'!C45 -> 438 | C31: ='Jewish adjustment'!D45 -> 149 | D31: ='Jewish adjustment'!E45 -> 226 | E31: ='Jewish adjustment'!F45 -> 597 | F31: ='Jewish adjustment'!G45 -> 313 | G31: ='Jewish adjustment'!H45 -> 183 | H31: =SUM(B31:G31) -> 1906 | J31: =IF(B$33=0,0,B31/B$33) -> 0.011941112 | K31: =IF(C$33=0,0,C31/C$33) -> 0.009222009 | L31: =IF(D$33=0,0,D31/D$33) -> 0.011228698 | M31: =IF(E$33=0,0,E31/E$33) -> 0.015048397 | N31: =IF(F$33=0,0,F31/F$33) -> 0.0091213755 | O31: =IF(G$33=0,0,G31/G$33) -> 0.0059903761 | P31: =IF(H$33=0,0,H31/H$33) -> 0.010738028
A32: Jewish (written in as ethnic group) – age split estimated | B32: ='Jewish adjustment'!C49 -> 11 | C32: ='Jewish adjustment'!D49 -> 12 | D32: ='Jewish adjustment'!E49 -> 9 | E32: ='Jewish adjustment'!F49 -> 20 | F32: ='Jewish adjustment'!G49 -> 24 | G32: ='Jewish adjustment'!H49 -> 20 | H32: =SUM(B32:G32) -> 96 | J32: =IF(B$33=0,0,B32/B$33) -> 0.00029989095 | K32: =IF(C$33=0,0,C32/C$33) -> 0.00074271214 | L32: =IF(D$33=0,0,D32/D$33) -> 0.00044716053 | M32: =IF(E$33=0,0,E32/E$33) -> 0.0005041339 | N32: =IF(F$33=0,0,F32/F$33) -> 0.00069940259 | O32: =IF(G$33=0,0,G32/G$33) -> 0.00065468591 | P32: =IF(H$33=0,0,H32/H$33) -> 0.00054084507
A33: All usual residents | B33: =B8+B14+B18+B23+B29+B32 -> 36680 | C33: =C8+C14+C18+C23+C29+C32 -> 16157 | D33: =D8+D14+D18+D23+D29+D32 -> 20127 | E33: =E8+E14+E18+E23+E29+E32 -> 39672 | F33: =F8+F14+F18+F23+F29+F32 -> 34315 | G33: =G8+G14+G18+G23+G29+G32 -> 30549 | H33: =SUM(B33:G33) -> 177500 | J33: =IF(B$33=0,0,B33/B$33) -> 1 | K33: =IF(C$33=0,0,C33/C$33) -> 1 | L33: =IF(D$33=0,0,D33/D$33) -> 1 | M33: =IF(E$33=0,0,E33/E$33) -> 1 | N33: =IF(F$33=0,0,F33/F$33) -> 1 | O33: =IF(G$33=0,0,G33/G$33) -> 1 | P33: =IF(H$33=0,0,H33/H$33) -> 1

Sheet Jewish adjustment
A1: Community United West Berkshire
A2: Jewish row – derivation of the age split
A3: Reference: CUDAT001 Version: v1.1.0
A4: Blue figures are keyed; black are formulas. See Notes for the method.
A6: South East age profile of people identifying as Jewish through the ethnic group question
C7: 0–15 | D7: 16–24 | E7: 25–34 | F7: 35–49 | G7: 50–64 | H7: 65+ | I7: All ages
A8: Count (ethnic group only + both), South East | C8: 536 | D8: 579 | E8: 460 | F8: 1020 | G8: 1155 | H8: 1005 | I8: =SUM(C8:H8) -> 4755
A9: Share of total | C9: =C8/$I$8 -> 0.11272345 | D9: =D8/$I$8 -> 0.12176656 | E9: =E8/$I$8 -> 0.096740273 | F9: =F8/$I$8 -> 0.21451104 | G9: =G8/$I$8 -> 0.24290221 | H9: =H8/$I$8 -> 0.21135647 | I9: =I8/$I$8 -> 1
A10: Age 15 is taken as one fifth of the 15–19 band.
A12: West Berkshire
A13: Row | B13: Measure | C13: 0–15 | D13: 16–24 | E13: 25–34 | F13: 35–49 | G13: 50–64 | H13: 65+ | I13: All ages | J13: Write-in total | K13: Check
A14: Other White | B14: ONS count | C14: 1238 | D14: 554 | E14: 1572 | F14: 3102 | G14: 1320 | H14: 593 | I14: =SUM(C14:H14) -> 8379
B15: Less: Jewish write-ins (estimate by age) | C15: 4 | D15: 4 | E15: 4 | F15: 8 | G15: 9 | H15: 8 | I15: =SUM(C15:H15) -> 37 | J15: 37 | K15: =IF(I15=J15,"OK","CHECK") -> OK
B16: Adjusted count | C16: =C14-C15 -> 1234 | D16: =D14-D15 -> 550 | E16: =E14-E15 -> 1568 | F16: =F14-F15 -> 3094 | G16: =G14-G15 -> 1311 | H16: =H14-H15 -> 585 | I16: =SUM(C16:H16) -> 8342
A17: Any other ethnic group | B17: ONS count | C17: 178 | D17: 70 | E17: 150 | F17: 281 | G17: 141 | H17: 87 | I17: =SUM(C17:H17) -> 907
B18: Less: Jewish write-ins (estimate by age) | C18: 2 | D18: 2 | E18: 2 | F18: 4 | G18: 4 | H18: 4 | I18: =SUM(C18:H18) -> 18 | J18: 18 | K18: =IF(I18=J18,"OK","CHECK") -> OK
B19: Adjusted count | C19: =C17-C18 -> 176 | D19: =D17-D18 -> 68 | E19: =E17-E18 -> 148 | F19: =F17-F18 -> 277 | G19: =G17-G18 -> 137 | H19: =H17-H18 -> 83 | I19: =SUM(C19:H19) -> 889
A20: Other Mixed | B20: ONS count | C20: 402 | D20: 136 | E20: 124 | F20: 214 | G20: 115 | H20: 35 | I20: =SUM(C20:H20) -> 1026
B21: Less: Jewish write-ins (estimate by age) | C21: 0 | D21: 0 | E21: 0 | F21: 1 | G21: 1 | H21: 1 | I21: =SUM(C21:H21) -> 3 | J21: 3 | K21: =IF(I21=J21,"OK","CHECK") -> OK
B22: Adjusted count | C22: =C20-C21 -> 402 | D22: =D20-D21 -> 136 | E22: =E20-E21 -> 124 | F22: =F20-F21 -> 213 | G22: =G20-G21 -> 114 | H22: =H20-H21 -> 34 | I22: =SUM(C22:H22) -> 1023
A23: Jewish (written in as ethnic group) | B23: Total of the three estimates | C23: =C15+C18+C21 -> 6 | D23: =D15+D18+D21 -> 6 | E23: =E15+E18+E21 -> 6 | F23: =F15+F18+F21 -> 13 | G23: =G15+G18+G21 -> 14 | H23: =H15+H18+H21 -> 13 | I23: =I15+I18+I21 -> 58
A25: Reading
A26: Row | B26: Measure | C26: 0–15 | D26: 16–24 | E26: 25–34 | F26: 35–49 | G26: 50–64 | H26: 65+ | I26: All ages | J26: Write-in total | K26: Check
A27: Other White | B27: ONS count | C27: 2930 | D27: 2344 | E27: 5827 | F27: 6977 | G27: 2157 | H27: 764 | I27: =SUM(C27:H27) -> 20999
B28: Less: Jewish write-ins (estimate by age) | C28: 5 | D28: 5 | E28: 4 | F28: 9 | G28: 11 | H28: 9 | I28: =SUM(C28:H28) -> 43 | J28: 43 | K28: =IF(I28=J28,"OK","CHECK") -> OK
B29: Adjusted count | C29: =C27-C28 -> 2925 | D29: =D27-D28 -> 2339 | E29: =E27-E28 -> 5823 | F29: =F27-F28 -> 6968 | G29: =G27-G28 -> 2146 | H29: =H27-H28 -> 755 | I29: =SUM(C29:H29) -> 20956
A30: Any other ethnic group | B30: ONS count | C30: 606 | D30: 477 | E30: 777 | F30: 1007 | G30: 506 | H30: 347 | I30: =SUM(C30:H30) -> 3720
B31: Less: Jewish write-ins (estimate by age) | C31: 6 | D31: 7 | E31: 5 | F31: 11 | G31: 13 | H31: 11 | I31: =SUM(C31:H31) -> 53 | J31: 53 | K31: =IF(I31=J31,"OK","CHECK") -> OK
B32: Adjusted count | C32: =C30-C31 -> 600 | D32: =D30-D31 -> 470 | E32: =E30-E31 -> 772 | F32: =F30-F31 -> 996 | G32: =G30-G31 -> 493 | H32: =H30-H31 -> 336 | I32: =SUM(C32:H32) -> 3667
A33: Other Mixed | B33: ONS count | C33: 789 | D33: 379 | E33: 315 | F33: 328 | G33: 163 | H33: 67 | I33: =SUM(C33:H33) -> 2041
B34: Less: Jewish write-ins (estimate by age) | C34: 1 | D34: 1 | E34: 1 | F34: 2 | G34: 2 | H34: 1 | I34: =SUM(C34:H34) -> 8 | J34: 8 | K34: =IF(I34=J34,"OK","CHECK") -> OK
B35: Adjusted count | C35: =C33-C34 -> 788 | D35: =D33-D34 -> 378 | E35: =E33-E34 -> 314 | F35: =F33-F34 -> 326 | G35: =G33-G34 -> 161 | H35: =H33-H34 -> 66 | I35: =SUM(C35:H35) -> 2033
A36: Jewish (written in as ethnic group) | B36: Total of the three estimates | C36: =C28+C31+C34 -> 12 | D36: =D28+D31+D34 -> 13 | E36: =E28+E31+E34 -> 10 | F36: =F28+F31+F34 -> 22 | G36: =G28+G31+G34 -> 26 | H36: =H28+H31+H34 -> 21 | I36: =I28+I31+I34 -> 104
A38: Wokingham
A39: Row | B39: Measure | C39: 0–15 | D39: 16–24 | E39: 25–34 | F39: 35–49 | G39: 50–64 | H39: 65+ | I39: All ages | J39: Write-in total | K39: Check
A40: Other White | B40: ONS count | C40: 1880 | D40: 800 | E40: 1682 | F40: 4144 | G40: 1560 | H40: 684 | I40: =SUM(C40:H40) -> 10750
B41: Less: Jewish write-ins (estimate by age) | C41: 5 | D41: 6 | E41: 4 | F41: 10 | G41: 11 | H41: 10 | I41: =SUM(C41:H41) -> 46 | J41: 46 | K41: =IF(I41=J41,"OK","CHECK") -> OK
B42: Adjusted count | C42: =C40-C41 -> 1875 | D42: =D40-D41 -> 794 | E42: =E40-E41 -> 1678 | F42: =F40-F41 -> 4134 | G42: =G40-G41 -> 1549 | H42: =H40-H41 -> 674 | I42: =SUM(C42:H42) -> 10704
A43: Any other ethnic group | B43: ONS count | C43: 444 | D43: 155 | E43: 231 | F43: 607 | G43: 325 | H43: 193 | I43: =SUM(C43:H43) -> 1955
B44: Less: Jewish write-ins (estimate by age) | C44: 6 | D44: 6 | E44: 5 | F44: 10 | G44: 12 | H44: 10 | I44: =SUM(C44:H44) -> 49 | J44: 49 | K44: =IF(I44=J44,"OK","CHECK") -> OK
...
